Workbook

Sheet Cleaned_Data
A1: Channel | B1: Region | C1: Fresh | D1: Milk | E1: Grocery | F1: Frozen | G1: Detergents_Paper | H1: Delicassen | I1: Channel_Name | J1: Region_Name | K1: Total_Annual_Spending
A2: 2 | B2: 3 | C2: 12669 | D2: 9656 | E2: 7561 | F2: 214 | G2: 2674 | H2: 1338 | I2: =IF(A2=1,"Horeca",IF(A2=2,"Retail","Check")) -> Retail | J2: =IF(B2=1,"Lisbon",IF(B2=2,"Oporto",IF(B2=3,"Other","Check"))) -> Other | K2: =SUM(C2:H2) -> 34112 | O2: Cleaning And Calculations
A3: 2 | B3: 3 | C3: 7057 | D3: 9810 | E3: 9568 | F3: 1762 | G3: 3293 | H3: 1776 | I3: =IF(A3=1,"Horeca",IF(A3=2,"Retail","Check")) -> Retail | J3: =IF(B3=1,"Lisbon",IF(B3=2,"Oporto",IF(B3=3,"Other","Check"))) -> Other | K3: =SUM(C3:H3) -> 33266 | O3: Blanks | Q3: FRESH SPEND
A4: 2 | B4: 3 | C4: 6353 | D4: 8808 | E4: 7684 | F4: 2405 | G4: 3516 | H4: 7844 | I4: =IF(A4=1,"Horeca",IF(A4=2,"Retail","Check")) -> Retail | J4: =IF(B4=1,"Lisbon",IF(B4=2,"Oporto",IF(B4=3,"Other","Check"))) -> Other | K4: =SUM(C4:H4) -> 36610 | O4: =COUNTBLANK(A2:A441) -> 0 | Q4: MIN SPEND: | R4: =MIN(C2:C441) -> 3
A5: 1 | B5: 3 | C5: 13265 | D5: 1196 | E5: 4221 | F5: 6404 | G5: 507 | H5: 1788 | I5: =IF(A5=1,"Horeca",IF(A5=2,"Retail","Check")) -> Horeca | J5: =IF(B5=1,"Lisbon",IF(B5=2,"Oporto",IF(B5=3,"Other","Check"))) -> Other | K5: =SUM(C5:H5) -> 27381 | O5: =COUNTBLANK(B2:B441) -> 0 | Q5: AVG SPEND: | R5: =AVERAGE(C2:C441) -> 12000.298
A6: 2 | B6: 3 | C6: 22615 | D6: 5410 | E6: 7198 | F6: 3915 | G6: 1777 | H6: 5185 | I6: =IF(A6=1,"Horeca",IF(A6=2,"Retail","Check")) -> Retail | J6: =IF(B6=1,"Lisbon",IF(B6=2,"Oporto",IF(B6=3,"Other","Check"))) -> Other | K6: =SUM(C6:H6) -> 46100 | O6: =COUNTBLANK(C2:C441) -> 0 | Q6: MAX SPEND: | R6: =MAX(C2:C440) -> 112151
A7: 2 | B7: 3 | C7: 9413 | D7: 8259 | E7: 5126 | F7: 666 | G7: 1795 | H7: 1451 | I7: =IF(A7=1,"Horeca",IF(A7=2,"Retail","Check")) -> Retail | J7: =IF(B7=1,"Lisbon",IF(B7=2,"Oporto",IF(B7=3,"Other","Check"))) -> Other | K7: =SUM(C7:H7) -> 26710 | O7: =COUNTBLANK(D2:D441) -> 0
A8: 2 | B8: 3 | C8: 12126 | D8: 3199 | E8: 6975 | F8: 480 | G8: 3140 | H8: 545 | I8: =IF(A8=1,"Horeca",IF(A8=2,"Retail","Check")) -> Retail | J8: =IF(B8=1,"Lisbon",IF(B8=2,"Oporto",IF(B8=3,"Other","Check"))) -> Other | K8: =SUM(C8:H8) -> 26465 | O8: =COUNTBLANK(E2:E441) -> 0 | Q8: MILK SPEND
A9: 2 | B9: 3 | C9: 7579 | D9: 4956 | E9: 9426 | F9: 1669 | G9: 3321 | H9: 2566 | I9: =IF(A9=1,"Horeca",IF(A9=2,"Retail","Check")) -> Retail | J9: =IF(B9=1,"Lisbon",IF(B9=2,"Oporto",IF(B9=3,"Other","Check"))) -> Other | K9: =SUM(C9:H9) -> 29517 | O9: =COUNTBLANK(F2:F441) -> 0 | Q9: MIN SPEND: | R9: =MIN(D2:D441) -> 55
A10: 1 | B10: 3 | C10: 5963 | D10: 3648 | E10: 6192 | F10: 425 | G10: 1716 | H10: 750 | I10: =IF(A10=1,"Horeca",IF(A10=2,"Retail","Check")) -> Horeca | J10: =IF(B10=1,"Lisbon",IF(B10=2,"Oporto",IF(B10=3,"Other","Check"))) -> Other | K10: =SUM(C10:H10) -> 18694 | O10: =COUNTBLANK(G2:G441) -> 0 | Q10: AVG SPEND: | R10: =AVERAGE(D2:D441) -> 5796.2659
A11: 2 | B11: 3 | C11: 6006 | D11: 11093 | E11: 18881 | F11: 1159 | G11: 7425 | H11: 2098 | I11: =IF(A11=1,"Horeca",IF(A11=2,"Retail","Check")) -> Retail | J11: =IF(B11=1,"Lisbon",IF(B11=2,"Oporto",IF(B11=3,"Other","Check"))) -> Other | K11: =SUM(C11:H11) -> 46662 | O11: =COUNTBLANK(H2:H441) -> 0 | Q11: MAX SPEND: | R11: =MAX(D2:D441) -> 73498
A12: 2 | B12: 3 | C12: 3366 | D12: 5403 | E12: 12974 | F12: 4400 | G12: 5977 | H12: 1744 | I12: =IF(A12=1,"Horeca",IF(A12=2,"Retail","Check")) -> Retail | J12: =IF(B12=1,"Lisbon",IF(B12=2,"Oporto",IF(B12=3,"Other","Check"))) -> Other | K12: =SUM(C12:H12) -> 33864
A13: 2 | B13: 3 | C13: 13146 | D13: 1124 | E13: 4523 | F13: 1420 | G13: 549 | H13: 497 | I13: =IF(A13=1,"Horeca",IF(A13=2,"Retail","Check")) -> Retail | J13: =IF(B13=1,"Lisbon",IF(B13=2,"Oporto",IF(B13=3,"Other","Check"))) -> Other | K13: =SUM(C13:H13) -> 21259 | Q13: GROCERY SPEND
A14: 2 | B14: 3 | C14: 31714 | D14: 12319 | E14: 11757 | F14: 287 | G14: 3881 | H14: 2931 | I14: =IF(A14=1,"Horeca",IF(A14=2,"Retail","Check")) -> Retail | J14: =IF(B14=1,"Lisbon",IF(B14=2,"Oporto",IF(B14=3,"Other","Check"))) -> Other | K14: =SUM(C14:H14) -> 62889 | Q14: MIN SPEND: | R14: =MIN(E2:E441) -> 3
A15: 2 | B15: 3 | C15: 21217 | D15: 6208 | E15: 14982 | F15: 3095 | G15: 6707 | H15: 602 | I15: =IF(A15=1,"Horeca",IF(A15=2,"Retail","Check")) -> Retail | J15: =IF(B15=1,"Lisbon",IF(B15=2,"Oporto",IF(B15=3,"Other","Check"))) -> Other | K15: =SUM(C15:H15) -> 52811 | Q15: AVG SPEND: | R15: =AVERAGE(E2:E441) -> 7951.2773
A16: 2 | B16: 3 | C16: 24653 | D16: 9465 | E16: 12091 | F16: 294 | G16: 5058 | H16: 2168 | I16: =IF(A16=1,"Horeca",IF(A16=2,"Retail","Check")) -> Retail | J16: =IF(B16=1,"Lisbon",IF(B16=2,"Oporto",IF(B16=3,"Other","Check"))) -> Other | K16: =SUM(C16:H16) -> 53729 | Q16: MAX SPEND: | R16: =MAX(E2:E441) -> 92780
A17: 1 | B17: 3 | C17: 10253 | D17: 1114 | E17: 3821 | F17: 397 | G17: 964 | H17: 412 | I17: =IF(A17=1,"Horeca",IF(A17=2,"Retail","Check")) -> Horeca | J17: =IF(B17=1,"Lisbon",IF(B17=2,"Oporto",IF(B17=3,"Other","Check"))) -> Other | K17: =SUM(C17:H17) -> 16961
A18: 2 | B18: 3 | C18: 1020 | D18: 8816 | E18: 12121 | F18: 134 | G18: 4508 | H18: 1080 | I18: =IF(A18=1,"Horeca",IF(A18=2,"Retail","Check")) -> Retail | J18: =IF(B18=1,"Lisbon",IF(B18=2,"Oporto",IF(B18=3,"Other","Check"))) -> Other | K18: =SUM(C18:H18) -> 27679 | Q18: FROZEN SPEND
A19: 1 | B19: 3 | C19: 5876 | D19: 6157 | E19: 2933 | F19: 839 | G19: 370 | H19: 4478 | I19: =IF(A19=1,"Horeca",IF(A19=2,"Retail","Check")) -> Horeca | J19: =IF(B19=1,"Lisbon",IF(B19=2,"Oporto",IF(B19=3,"Other","Check"))) -> Other | K19: =SUM(C19:H19) -> 20653 | Q19: MIN SPEND: | R19: =MIN(F2:F441) -> 25
A20: 2 | B20: 3 | C20: 18601 | D20: 6327 | E20: 10099 | F20: 2205 | G20: 2767 | H20: 3181 | I20: =IF(A20=1,"Horeca",IF(A20=2,"Retail","Check")) -> Retail | J20: =IF(B20=1,"Lisbon",IF(B20=2,"Oporto",IF(B20=3,"Other","Check"))) -> Other | K20: =SUM(C20:H20) -> 43180 | Q20: AVG SPEND: | R20: =AVERAGE(F2:F441) -> 3071.9318
A21: 1 | B21: 3 | C21: 7780 | D21: 2495 | E21: 9464 | F21: 669 | G21: 2518 | H21: 501 | I21: =IF(A21=1,"Horeca",IF(A21=2,"Retail","Check")) -> Horeca | J21: =IF(B21=1,"Lisbon",IF(B21=2,"Oporto",IF(B21=3,"Other","Check"))) -> Other | K21: =SUM(C21:H21) -> 23427 | Q21: MAX SPEND: | R21: =MAX(F2:F441) -> 60869
A22: 2 | B22: 3 | C22: 17546 | D22: 4519 | E22: 4602 | F22: 1066 | G22: 2259 | H22: 2124 | I22: =IF(A22=1,"Horeca",IF(A22=2,"Retail","Check")) -> Retail | J22: =IF(B22=1,"Lisbon",IF(B22=2,"Oporto",IF(B22=3,"Other","Check"))) -> Other | K22: =SUM(C22:H22) -> 32116
A23: 1 | B23: 3 | C23: 5567 | D23: 871 | E23: 2010 | F23: 3383 | G23: 375 | H23: 569 | I23: =IF(A23=1,"Horeca",IF(A23=2,"Retail","Check")) -> Horeca | J23: =IF(B23=1,"Lisbon",IF(B23=2,"Oporto",IF(B23=3,"Other","Check"))) -> Other | K23: =SUM(C23:H23) -> 12775 | Q23: DETERGENTS_PAPER
A24: 1 | B24: 3 | C24: 31276 | D24: 1917 | E24: 4469 | F24: 9408 | G24: 2381 | H24: 4334 | I24: =IF(A24=1,"Horeca",IF(A24=2,"Retail","Check")) -> Horeca | J24: =IF(B24=1,"Lisbon",IF(B24=2,"Oporto",IF(B24=3,"Other","Check"))) -> Other | K24: =SUM(C24:H24) -> 53785 | Q24: MIN SPEND: | R24: =MIN(G2:G441) -> 3
A25: 2 | B25: 3 | C25: 26373 | D25: 36423 | E25: 22019 | F25: 5154 | G25: 4337 | H25: 16523 | I25: =IF(A25=1,"Horeca",IF(A25=2,"Retail","Check")) -> Retail | J25: =IF(B25=1,"Lisbon",IF(B25=2,"Oporto",IF(B25=3,"Other","Check"))) -> Other | K25: =SUM(C25:H25) -> 110829 | Q25: AVG SPEND: | R25: =AVERAGE(G2:G441) -> 2881.4932
A26: 2 | B26: 3 | C26: 22647 | D26: 9776 | E26: 13792 | F26: 2915 | G26: 4482 | H26: 5778 | I26: =IF(A26=1,"Horeca",IF(A26=2,"Retail","Check")) -> Retail | J26: =IF(B26=1,"Lisbon",IF(B26=2,"Oporto",IF(B26=3,"Other","Check"))) -> Other | K26: =SUM(C26:H26) -> 59390 | Q26: MAX SPEND: | R26: =MAX(G2:G441) -> 40827
A27: 2 | B27: 3 | C27: 16165 | D27: 4230 | E27: 7595 | F27: 201 | G27: 4003 | H27: 57 | I27: =IF(A27=1,"Horeca",IF(A27=2,"Retail","Check")) -> Retail | J27: =IF(B27=1,"Lisbon",IF(B27=2,"Oporto",IF(B27=3,"Other","Check"))) -> Other | K27: =SUM(C27:H27) -> 32251
A28: 1 | B28: 3 | C28: 9898 | D28: 961 | E28: 2861 | F28: 3151 | G28: 242 | H28: 833 | I28: =IF(A28=1,"Horeca",IF(A28=2,"Retail","Check")) -> Horeca | J28: =IF(B28=1,"Lisbon",IF(B28=2,"Oporto",IF(B28=3,"Other","Check"))) -> Other | K28: =SUM(C28:H28) -> 17946 | Q28: DELICASSAN
A29: 1 | B29: 3 | C29: 14276 | D29: 803 | E29: 3045 | F29: 485 | G29: 100 | H29: 518 | I29: =IF(A29=1,"Horeca",IF(A29=2,"Retail","Check")) -> Horeca | J29: =IF(B29=1,"Lisbon",IF(B29=2,"Oporto",IF(B29=3,"Other","Check"))) -> Other | K29: =SUM(C29:H29) -> 19227 | Q29: MIN SPEND: | R29: =MIN(H2:H441) -> 3
A30: 2 | B30: 3 | C30: 4113 | D30: 20484 | E30: 25957 | F30: 1158 | G30: 8604 | H30: 5206 | I30: =IF(A30=1,"Horeca",IF(A30=2,"Retail","Check")) -> Retail | J30: =IF(B30=1,"Lisbon",IF(B30=2,"Oporto",IF(B30=3,"Other","Check"))) -> Other | K30: =SUM(C30:H30) -> 65522 | Q30: AVG SPEND: | R30: =AVERAGE(H2:H441) -> 1524.8705
A31: 1 | B31: 3 | C31: 43088 | D31: 2100 | E31: 2609 | F31: 1200 | G31: 1107 | H31: 823 | I31: =IF(A31=1,"Horeca",IF(A31=2,"Retail","Check")) -> Horeca | J31: =IF(B31=1,"Lisbon",IF(B31=2,"Oporto",IF(B31=3,"Other","Check"))) -> Other | K31: =SUM(C31:H31) -> 50927 | Q31: MAX SPEND: | R31: =MAX(H2:H441) -> 47943
A32: 1 | B32: 3 | C32: 18815 | D32: 3610 | E32: 11107 | F32: 1148 | G32: 2134 | H32: 2963 | I32: =IF(A32=1,"Horeca",IF(A32=2,"Retail","Check")) -> Horeca | J32: =IF(B32=1,"Lisbon",IF(B32=2,"Oporto",IF(B32=3,"Other","Check"))) -> Other | K32: =SUM(C32:H32) -> 39777
A33: 1 | B33: 3 | C33: 2612 | D33: 4339 | E33: 3133 | F33: 2088 | G33: 820 | H33: 985 | I33: =IF(A33=1,"Horeca",IF(A33=2,"Retail","Check")) -> Horeca | J33: =IF(B33=1,"Lisbon",IF(B33=2,"Oporto",IF(B33=3,"Other","Check"))) -> Other | K33: =SUM(C33:H33) -> 13977
A34: 1 | B34: 3 | C34: 21632 | D34: 1318 | E34: 2886 | F34: 266 | G34: 918 | H34: 405 | I34: =IF(A34=1,"Horeca",IF(A34=2,"Retail","Check")) -> Horeca | J34: =IF(B34=1,"Lisbon",IF(B34=2,"Oporto",IF(B34=3,"Other","Check"))) -> Other | K34: =SUM(C34:H34) -> 27425
A35: 1 | B35: 3 | C35: 29729 | D35: 4786 | E35: 7326 | F35: 6130 | G35: 361 | H35: 1083 | I35: =IF(A35=1,"Horeca",IF(A35=2,"Retail","Check")) -> Horeca | J35: =IF(B35=1,"Lisbon",IF(B35=2,"Oporto",IF(B35=3,"Other","Check"))) -> Other | K35: =SUM(C35:H35) -> 49415
A36: 1 | B36: 3 | C36: 1502 | D36: 1979 | E36: 2262 | F36: 425 | G36: 483 | H36: 395 | I36: =IF(A36=1,"Horeca",IF(A36=2,"Retail","Check")) -> Horeca | J36: =IF(B36=1,"Lisbon",IF(B36=2,"Oporto",IF(B36=3,"Other","Check"))) -> Other | K36: =SUM(C36:H36) -> 7046
A37: 2 | B37: 3 | C37: 688 | D37: 5491 | E37: 11091 | F37: 833 | G37: 4239 | H37: 436 | I37: =IF(A37=1,"Horeca",IF(A37=2,"Retail","Check")) -> Retail | J37: =IF(B37=1,"Lisbon",IF(B37=2,"Oporto",IF(B37=3,"Other","Check"))) -> Other | K37: =SUM(C37:H37) -> 22778
A38: 1 | B38: 3 | C38: 29955 | D38: 4362 | E38: 5428 | F38: 1729 | G38: 862 | H38: 4626 | I38: =IF(A38=1,"Horeca",IF(A38=2,"Retail","Check")) -> Horeca | J38: =IF(B38=1,"Lisbon",IF(B38=2,"Oporto",IF(B38=3,"Other","Check"))) -> Other | K38: =SUM(C38:H38) -> 46962
A39: 2 | B39: 3 | C39: 15168 | D39: 10556 | E39: 12477 | F39: 1920 | G39: 6506 | H39: 714 | I39: =IF(A39=1,"Horeca",IF(A39=2,"Retail","Check")) -> Retail | J39: =IF(B39=1,"Lisbon",IF(B39=2,"Oporto",IF(B39=3,"Other","Check"))) -> Other | K39: =SUM(C39:H39) -> 47341
A40: 2 | B40: 3 | C40: 4591 | D40: 15729 | E40: 16709 | F40: 33 | G40: 6956 | H40: 433 | I40: =IF(A40=1,"Horeca",IF(A40=2,"Retail","Check")) -> Retail | J40: =IF(B40=1,"Lisbon",IF(B40=2,"Oporto",IF(B40=3,"Other","Check"))) -> Other | K40: =SUM(C40:H40) -> 44451
...

Sheet Cleaning_Log
A1: Cleaning Check | B1: Method | C1: Result
A2: Column headers | B2: Compared with dataset documentation | C2: Accurate
A3: Missing values | B3: COUNTBLANK | C3: None
A4: Duplicates | B4: Exact-row comparison, Conditional Formatting | C4: None
A5: Data types | B5: ISNUMBER and cell formatting | C5: True
A6: Channel and Region | B6: Checked category codes | C6: Accurate
A7: Negative spending | B7: MIN and number filters | C7: Checked
A8: Outliers | B8: MAX and summary statistics | C8: Checked

Sheet Raw_Data
A1: Channel | B1: Region | C1: Fresh | D1: Milk | E1: Grocery | F1: Frozen | G1: Detergents_Paper | H1: Delicassen
A2: 2 | B2: 3 | C2: 12669 | D2: 9656 | E2: 7561 | F2: 214 | G2: 2674 | H2: 1338
A3: 2 | B3: 3 | C3: 7057 | D3: 9810 | E3: 9568 | F3: 1762 | G3: 3293 | H3: 1776
A4: 2 | B4: 3 | C4: 6353 | D4: 8808 | E4: 7684 | F4: 2405 | G4: 3516 | H4: 7844
A5: 1 | B5: 3 | C5: 13265 | D5: 1196 | E5: 4221 | F5: 6404 | G5: 507 | H5: 1788
A6: 2 | B6: 3 | C6: 22615 | D6: 5410 | E6: 7198 | F6: 3915 | G6: 1777 | H6: 5185
A7: 2 | B7: 3 | C7: 9413 | D7: 8259 | E7: 5126 | F7: 666 | G7: 1795 | H7: 1451
A8: 2 | B8: 3 | C8: 12126 | D8: 3199 | E8: 6975 | F8: 480 | G8: 3140 | H8: 545
A9: 2 | B9: 3 | C9: 7579 | D9: 4956 | E9: 9426 | F9: 1669 | G9: 3321 | H9: 2566
A10: 1 | B10: 3 | C10: 5963 | D10: 3648 | E10: 6192 | F10: 425 | G10: 1716 | H10: 750
A11: 2 | B11: 3 | C11: 6006 | D11: 11093 | E11: 18881 | F11: 1159 | G11: 7425 | H11: 2098
A12: 2 | B12: 3 | C12: 3366 | D12: 5403 | E12: 12974 | F12: 4400 | G12: 5977 | H12: 1744
A13: 2 | B13: 3 | C13: 13146 | D13: 1124 | E13: 4523 | F13: 1420 | G13: 549 | H13: 497
... A441: 1 | B441: 3 | C441: 2787 | D441: 1698 | E441: 2510 | F441: 65 | G441: 477 | H441: 52

Sheet Analysis
A1: Product_Category | B1: Total_Spending | C1: Average_Spending | E1: Channel | F1: Customer_Count | G1: Average_Spending | H1: Total_Spending
A2: Fresh | B2: =SUM(Cleaned_Data!C2:C441) -> 5280131 | C2: =AVERAGE(Cleaned_Data!C2:C441) -> 12000.298 | E2: Horeca | F2: =COUNTIF(Cleaned_Data!I2:I441,E2) -> 298 | G2: =AVERAGEIF(Cleaned_Data!I2:I441,E2,Cleaned_Data!K2:K441) -> 26844.191 | H2: =SUMIF(Cleaned_Data!I2:I441,E2,Cleaned_Data!K2:K441) -> 7999569
A3: Milk | B3: =SUM(Cleaned_Data!D2:D441) -> 2550357 | C3: =AVERAGE(Cleaned_Data!D2:D441) -> 5796.2659 | E3: Retail | F3: =COUNTIF(Cleaned_Data!I2:I441,E3) -> 142 | G3: =AVERAGEIF(Cleaned_Data!I2:I441,E3,Cleaned_Data!K2:K441) -> 46619.232 | H3: =SUMIF(Cleaned_Data!I2:I441,E3,Cleaned_Data!K2:K441) -> 6619931
A4: Grocery | B4: =SUM(Cleaned_Data!E2:E441) -> 3498562 | C4: =AVERAGE(Cleaned_Data!E2:E441) -> 7951.2773
A5: Frozen | B5: =SUM(Cleaned_Data!F2:F441) -> 1351650 | C5: =AVERAGE(Cleaned_Data!F2:F441) -> 3071.9318
A6: Detergents_Paper | B6: =SUM(Cleaned_Data!G2:G441) -> 1267857 | C6: =AVERAGE(Cleaned_Data!G2:G441) -> 2881.4932
A7: Delicassen | B7: =SUM(Cleaned_Data!H2:H441) -> 670943 | C7: =AVERAGE(Cleaned_Data!H2:H441) -> 1524.8705
A9: Highest_Spending_Category | B9: =INDEX(A2:A7,MATCH(MAX(B2:B7),B2:B7,0)) -> Fresh
A10: Lowest_Spending_Category | B10: =INDEX(A2:A7,MATCH(MIN(B2:B7),B2:B7,0)) -> Delicassen
A13: Region | B13: Customer_Count | C13: Average_Spending | D13: Total_Spending
A14: Lisbon | B14: =COUNTIF(Cleaned_Data!J$2:J$441,A14) -> 77 | C14: =AVERAGEIF(Cleaned_Data!J$2:J$441,A14,Cleaned_Data!K$2:K$441) -> 30997.571 | D14: =SUMIF(Cleaned_Data!J$2:J$441,A14,Cleaned_Data!K$2:K$441) -> 2386813
A15: Oporto | B15: =COUNTIF(Cleaned_Data!J$2:J$441,A15) -> 47 | C15: =AVERAGEIF(Cleaned_Data!J$2:J$441,A15,Cleaned_Data!K$2:K$441) -> 33086.979 | D15: =SUMIF(Cleaned_Data!J$2:J$441,A15,Cleaned_Data!K$2:K$441) -> 1555088
A16: Other | B16: =COUNTIF(Cleaned_Data!J$2:J$441,A16) -> 316 | C16: =AVERAGEIF(Cleaned_Data!J$2:J$441,A16,Cleaned_Data!K$2:K$441) -> 33789.87 | D16: =SUMIF(Cleaned_Data!J$2:J$441,A16,Cleaned_Data!K$2:K$441) -> 10677599
A19: Product_Category | B19: Horeca_Average | C19: Retail_Average
A20: Fresh | B20: =AVERAGEIF(Cleaned_Data!$I$2:$I$441,"Horeca",Cleaned_Data!C$2:C$441) -> 13475.56 | C20: =AVERAGEIF(Cleaned_Data!$I$2:$I$441,"Retail",Cleaned_Data!C$2:C$441) -> 8904.3239
A21: Milk | B21: =AVERAGEIF(Cleaned_Data!$I$2:$I$441,"Horeca",Cleaned_Data!D$2:D$441) -> 3451.7248 | C21: =AVERAGEIF(Cleaned_Data!$I$2:$I$441,"Retail",Cleaned_Data!D$2:D$441) -> 10716.5
A22: Grocery | B22: =AVERAGEIF(Cleaned_Data!$I$2:$I$441,"Horeca",Cleaned_Data!E$2:E$441) -> 3962.1376 | C22: =AVERAGEIF(Cleaned_Data!$I$2:$I$441,"Retail",Cleaned_Data!E$2:E$441) -> 16322.852
A23: Frozen | B23: =AVERAGEIF(Cleaned_Data!$I$2:$I$441,"Horeca",Cleaned_Data!F$2:F$441) -> 3748.2517 | C23: =AVERAGEIF(Cleaned_Data!$I$2:$I$441,"Retail",Cleaned_Data!F$2:F$441) -> 1652.6127
A24: Detergents_Paper | B24: =AVERAGEIF(Cleaned_Data!$I$2:$I$441,"Horeca",Cleaned_Data!G$2:G$441) -> 790.5604 | C24: =AVERAGEIF(Cleaned_Data!$I$2:$I$441,"Retail",Cleaned_Data!G$2:G$441) -> 7269.507
A25: Delicassen | B25: =AVERAGEIF(Cleaned_Data!$I$2:$I$441,"Horeca",Cleaned_Data!H$2:H$441) -> 1415.9564 | C25: =AVERAGEIF(Cleaned_Data!$I$2:$I$441,"Retail",Cleaned_Data!H$2:H$441) -> 1753.4366

Sheet Dashboard
A1: WHOLESALE CUSTOMER SPENDING DASHBOARD
A3: Total Customers | C3: Total Annual Spending | E3: Average Spending per Customer | G3: Highest Spending Category
A4: =COUNTA(Cleaned_Data!A2:A441) -> 440 | C4: =SUM(Cleaned_Data!K2:K441) -> 14619500 | E4: =AVERAGE(Cleaned_Data!K2:K441) -> 33226.136 | G4: =Analysis!B9 -> Fresh
A38: KEY INSIGHTS
A39: Fresh has the highest total spending across product categories.
A40: Retail customers have higher average spending than Horeca customers.
A41: The Other region has the highest average spending per customer.
